Workbook

Sheet SIMOPS
A1: SIMOPS — Ordens programadas para o dia
A2: Fonte: aba BASELINE (colar a exportação atualizada em A:T). Só é preciso informar a data abaixo.
A3: Data de execução | D3: =TODAY()+1 | E3: =TEXT(D3,"dddd") | G3: Operações | I3: =COUNT($A$9:$A$158) | J3: Break-in | K3: =COUNTIF($J$9:$J$158,"SIM")
A4: Ordens encerradas ficam de fora | E4: ← D3 vem como amanhã (=HOJE()+1); digite outra data para sobrescrever | G4: Ordens | I4: =SUMPRODUCT(($B$9:$B$158<>"")/COUNTIF($B$9:$B$158,$B$9:$B$158&""))
G5: HH total | I5: =SUM($F$9:$F$158)
A6: =IF(CALC!$D$1>150,"ATENÇÃO: "&CALC!$D$1&" operações no dia, mas a lista mostra só 150. Estenda as fórmulas para baixo.","")
A8: # | B8: Ordem | C8: Op. | D8: Descrição da ordem | E8: Descrição da operação | F8: HH | G8: Centro de trabalho | H8: Local de instalação | I8: Denominação do LI | J8: Break-in | K8: lin
A9: =IF($K9="","",1) | B9: =IF($K9="","",IF(INDEX(BASELINE!$I$2:$I$3001,$K9)="","",INDEX(BASELINE!$I$2:$I$3001,$K9))) | C9: =IF($K9="","",IF(INDEX(BASELINE!$J$2:$J$3001,$K9)="","",INDEX(BASELINE!$J$2:$J$3001,$K9))) | D9: =IF($K9="","",IF(INDEX(BASELINE!$M$2:$M$3001,$K9)="","",INDEX(BASELINE!$M$2:$M$3001,$K9))) | E9: =IF($K9="","",IF(INDEX(BASELINE!$L$2:$L$3001,$K9)="","",INDEX(BASELINE!$L$2:$L$3001,$K9))) | F9: =IF($K9="","",IF(INDEX(BASELINE!$P$2:$P$3001,$K9)="","",INDEX(BASELINE!$P$2:$P$3001,$K9))) | G9: =IF($K9="","",IF(INDEX(BASELINE!$K$2:$K$3001,$K9)="","",INDEX(BASELINE!$K$2:$K$3001,$K9))) | H9: =IF($K9="","",IF(INDEX(BASELINE!$N$2:$N$3001,$K9)="","",INDEX(BASELINE!$N$2:$N$3001,$K9))) | I9: =IF($K9="","",IF(INDEX(BASELINE!$O$2:$O$3001,$K9)="","",INDEX(BASELINE!$O$2:$O$3001,$K9))) | J9: =IF($K9="","",IF(ISNUMBER(SEARCH("break",INDEX(BASELINE!$T$2:$T$3001,$K9)&"")),"SIM","")) | K9: =IF(1<=CALC!$D$1,MATCH(1,CALC!$B$2:$B$3001,0),"")
A10: =IF($K10="","",2) | B10: =IF($K10="","",IF(INDEX(BASELINE!$I$2:$I$3001,$K10)="","",INDEX(BASELINE!$I$2:$I$3001,$K10))) | C10: =IF($K10="","",IF(INDEX(BASELINE!$J$2:$J$3001,$K10)="","",INDEX(BASELINE!$J$2:$J$3001,$K10))) | D10: =IF($K10="","",IF(INDEX(BASELINE!$M$2:$M$3001,$K10)="","",INDEX(BASELINE!$M$2:$M$3001,$K10))) | E10: =IF($K10="","",IF(INDEX(BASELINE!$L$2:$L$3001,$K10)="","",INDEX(BASELINE!$L$2:$L$3001,$K10))) | F10: =IF($K10="","",IF(INDEX(BASELINE!$P$2:$P$3001,$K10)="","",INDEX(BASELINE!$P$2:$P$3001,$K10))) | G10: =IF($K10="","",IF(INDEX(BASELINE!$K$2:$K$3001,$K10)="","",INDEX(BASELINE!$K$2:$K$3001,$K10))) | H10: =IF($K10="","",IF(INDEX(BASELINE!$N$2:$N$3001,$K10)="","",INDEX(BASELINE!$N$2:$N$3001,$K10))) | I10: =IF($K10="","",IF(INDEX(BASELINE!$O$2:$O$3001,$K10)="","",INDEX(BASELINE!$O$2:$O$3001,$K10))) | J10: =IF($K10="","",IF(ISNUMBER(SEARCH("break",INDEX(BASELINE!$T$2:$T$3001,$K10)&"")),"SIM","")) | K10: =IF(2<=CALC!$D$1,MATCH(2,CALC!$B$2:$B$3001,0),"")
A11: =IF($K11="","",3) | B11: =IF($K11="","",IF(INDEX(BASELINE!$I$2:$I$3001,$K11)="","",INDEX(BASELINE!$I$2:$I$3001,$K11))) | C11: =IF($K11="","",IF(INDEX(BASELINE!$J$2:$J$3001,$K11)="","",INDEX(BASELINE!$J$2:$J$3001,$K11))) | D11: =IF($K11="","",IF(INDEX(BASELINE!$M$2:$M$3001,$K11)="","",INDEX(BASELINE!$M$2:$M$3001,$K11))) | E11: =IF($K11="","",IF(INDEX(BASELINE!$L$2:$L$3001,$K11)="","",INDEX(BASELINE!$L$2:$L$3001,$K11))) | F11: =IF($K11="","",IF(INDEX(BASELINE!$P$2:$P$3001,$K11)="","",INDEX(BASELINE!$P$2:$P$3001,$K11))) | G11: =IF($K11="","",IF(INDEX(BASELINE!$K$2:$K$3001,$K11)="","",INDEX(BASELINE!$K$2:$K$3001,$K11))) | H11: =IF($K11="","",IF(INDEX(BASELINE!$N$2:$N$3001,$K11)="","",INDEX(BASELINE!$N$2:$N$3001,$K11))) | I11: =IF($K11="","",IF(INDEX(BASELINE!$O$2:$O$3001,$K11)="","",INDEX(BASELINE!$O$2:$O$3001,$K11))) | J11: =IF($K11="","",IF(ISNUMBER(SEARCH("break",INDEX(BASELINE!$T$2:$T$3001,$K11)&"")),"SIM","")) | K11: =IF(3<=CALC!$D$1,MATCH(3,CALC!$B$2:$B$3001,0),"")
A12: =IF($K12="","",4) | B12: =IF($K12="","",IF(INDEX(BASELINE!$I$2:$I$3001,$K12)="","",INDEX(BASELINE!$I$2:$I$3001,$K12))) | C12: =IF($K12="","",IF(INDEX(BASELINE!$J$2:$J$3001,$K12)="","",INDEX(BASELINE!$J$2:$J$3001,$K12))) | D12: =IF($K12="","",IF(INDEX(BASELINE!$M$2:$M$3001,$K12)="","",INDEX(BASELINE!$M$2:$M$3001,$K12))) | E12: =IF($K12="","",IF(INDEX(BASELINE!$L$2:$L$3001,$K12)="","",INDEX(BASELINE!$L$2:$L$3001,$K12))) | F12: =IF($K12="","",IF(INDEX(BASELINE!$P$2:$P$3001,$K12)="","",INDEX(BASELINE!$P$2:$P$3001,$K12))) | G12: =IF($K12="","",IF(INDEX(BASELINE!$K$2:$K$3001,$K12)="","",INDEX(BASELINE!$K$2:$K$3001,$K12))) | H12: =IF($K12="","",IF(INDEX(BASELINE!$N$2:$N$3001,$K12)="","",INDEX(BASELINE!$N$2:$N$3001,$K12))) | I12: =IF($K12="","",IF(INDEX(BASELINE!$O$2:$O$3001,$K12)="","",INDEX(BASELINE!$O$2:$O$3001,$K12))) | J12: =IF($K12="","",IF(ISNUMBER(SEARCH("break",INDEX(BASELINE!$T$2:$T$3001,$K12)&"")),"SIM","")) | K12: =IF(4<=CALC!$D$1,MATCH(4,CALC!$B$2:$B$3001,0),"")
A13: =IF($K13="","",5) | B13: =IF($K13="","",IF(INDEX(BASELINE!$I$2:$I$3001,$K13)="","",INDEX(BASELINE!$I$2:$I$3001,$K13))) | C13: =IF($K13="","",IF(INDEX(BASELINE!$J$2:$J$3001,$K13)="","",INDEX(BASELINE!$J$2:$J$3001,$K13))) | D13: =IF($K13="","",IF(INDEX(BASELINE!$M$2:$M$3001,$K13)="","",INDEX(BASELINE!$M$2:$M$3001,$K13))) | E13: =IF($K13="","",IF(INDEX(BASELINE!$L$2:$L$3001,$K13)="","",INDEX(BASELINE!$L$2:$L$3001,$K13))) | F13: =IF($K13="","",IF(INDEX(BASELINE!$P$2:$P$3001,$K13)="","",INDEX(BASELINE!$P$2:$P$3001,$K13))) | G13: =IF($K13="","",IF(INDEX(BASELINE!$K$2:$K$3001,$K13)="","",INDEX(BASELINE!$K$2:$K$3001,$K13))) | H13: =IF($K13="","",IF(INDEX(BASELINE!$N$2:$N$3001,$K13)="","",INDEX(BASELINE!$N$2:$N$3001,$K13))) | I13: =IF($K13="","",IF(INDEX(BASELINE!$O$2:$O$3001,$K13)="","",INDEX(BASELINE!$O$2:$O$3001,$K13))) | J13: =IF($K13="","",IF(ISNUMBER(SEARCH("break",INDEX(BASELINE!$T$2:$T$3001,$K13)&"")),"SIM","")) | K13: =IF(5<=CALC!$D$1,MATCH(5,CALC!$B$2:$B$3001,0),"")
A14: =IF($K14="","",6) | B14: =IF($K14="","",IF(INDEX(BASELINE!$I$2:$I$3001,$K14)="","",INDEX(BASELINE!$I$2:$I$3001,$K14))) | C14: =IF($K14="","",IF(INDEX(BASELINE!$J$2:$J$3001,$K14)="","",INDEX(BASELINE!$J$2:$J$3001,$K14))) | D14: =IF($K14="","",IF(INDEX(BASELINE!$M$2:$M$3001,$K14)="","",INDEX(BASELINE!$M$2:$M$3001,$K14))) | E14: =IF($K14="","",IF(INDEX(BASELINE!$L$2:$L$3001,$K14)="","",INDEX(BASELINE!$L$2:$L$3001,$K14))) | F14: =IF($K14="","",IF(INDEX(BASELINE!$P$2:$P$3001,$K14)="","",INDEX(BASELINE!$P$2:$P$3001,$K14))) | G14: =IF($K14="","",IF(INDEX(BASELINE!$K$2:$K$3001,$K14)="","",INDEX(BASELINE!$K$2:$K$3001,$K14))) | H14: =IF($K14="","",IF(INDEX(BASELINE!$N$2:$N$3001,$K14)="","",INDEX(BASELINE!$N$2:$N$3001,$K14))) | I14: =IF($K14="","",IF(INDEX(BASELINE!$O$2:$O$3001,$K14)="","",INDEX(BASELINE!$O$2:$O$3001,$K14))) | J14: =IF($K14="","",IF(ISNUMBER(SEARCH("break",INDEX(BASELINE!$T$2:$T$3001,$K14)&"")),"SIM","")) | K14: =IF(6<=CALC!$D$1,MATCH(6,CALC!$B$2:$B$3001,0),"")
A15: =IF($K15="","",7) | B15: =IF($K15="","",IF(INDEX(BASELINE!$I$2:$I$3001,$K15)="","",INDEX(BASELINE!$I$2:$I$3001,$K15))) | C15: =IF($K15="","",IF(INDEX(BASELINE!$J$2:$J$3001,$K15)="","",INDEX(BASELINE!$J$2:$J$3001,$K15))) | D15: =IF($K15="","",IF(INDEX(BASELINE!$M$2:$M$3001,$K15)="","",INDEX(BASELINE!$M$2:$M$3001,$K15))) | E15: =IF($K15="","",IF(INDEX(BASELINE!$L$2:$L$3001,$K15)="","",INDEX(BASELINE!$L$2:$L$3001,$K15))) | F15: =IF($K15="","",IF(INDEX(BASELINE!$P$2:$P$3001,$K15)="","",INDEX(BASELINE!$P$2:$P$3001,$K15))) | G15: =IF($K15="","",IF(INDEX(BASELINE!$K$2:$K$3001,$K15)="","",INDEX(BASELINE!$K$2:$K$3001,$K15))) | H15: =IF($K15="","",IF(INDEX(BASELINE!$N$2:$N$3001,$K15)="","",INDEX(BASELINE!$N$2:$N$3001,$K15))) | I15: =IF($K15="","",IF(INDEX(BASELINE!$O$2:$O$3001,$K15)="","",INDEX(BASELINE!$O$2:$O$3001,$K15))) | J15: =IF($K15="","",IF(ISNUMBER(SEARCH("break",INDEX(BASELINE!$T$2:$T$3001,$K15)&"")),"SIM","")) | K15: =IF(7<=CALC!$D$1,MATCH(7,CALC!$B$2:$B$3001,0),"")
A16: =IF($K16="","",8) | B16: =IF($K16="","",IF(INDEX(BASELINE!$I$2:$I$3001,$K16)="","",INDEX(BASELINE!$I$2:$I$3001,$K16))) | C16: =IF($K16="","",IF(INDEX(BASELINE!$J$2:$J$3001,$K16)="","",INDEX(BASELINE!$J$2:$J$3001,$K16))) | D16: =IF($K16="","",IF(INDEX(BASELINE!$M$2:$M$3001,$K16)="","",INDEX(BASELINE!$M$2:$M$3001,$K16))) | E16: =IF($K16="","",IF(INDEX(BASELINE!$L$2:$L$3001,$K16)="","",INDEX(BASELINE!$L$2:$L$3001,$K16))) | F16: =IF($K16="","",IF(INDEX(BASELINE!$P$2:$P$3001,$K16)="","",INDEX(BASELINE!$P$2:$P$3001,$K16))) | G16: =IF($K16="","",IF(INDEX(BASELINE!$K$2:$K$3001,$K16)="","",INDEX(BASELINE!$K$2:$K$3001,$K16))) | H16: =IF($K16="","",IF(INDEX(BASELINE!$N$2:$N$3001,$K16)="","",INDEX(BASELINE!$N$2:$N$3001,$K16))) | I16: =IF($K16="","",IF(INDEX(BASELINE!$O$2:$O$3001,$K16)="","",INDEX(BASELINE!$O$2:$O$3001,$K16))) | J16: =IF($K16="","",IF(ISNUMBER(SEARCH("break",INDEX(BASELINE!$T$2:$T$3001,$K16)&"")),"SIM","")) | K16: =IF(8<=CALC!$D$1,MATCH(8,CALC!$B$2:$B$3001,0),"")
A17: =IF($K17="","",9) | B17: =IF($K17="","",IF(INDEX(BASELINE!$I$2:$I$3001,$K17)="","",INDEX(BASELINE!$I$2:$I$3001,$K17))) | C17: =IF($K17="","",IF(INDEX(BASELINE!$J$2:$J$3001,$K17)="","",INDEX(BASELINE!$J$2:$J$3001,$K17))) | D17: =IF($K17="","",IF(INDEX(BASELINE!$M$2:$M$3001,$K17)="","",INDEX(BASELINE!$M$2:$M$3001,$K17))) | E17: =IF($K17="","",IF(INDEX(BASELINE!$L$2:$L$3001,$K17)="","",INDEX(BASELINE!$L$2:$L$3001,$K17))) | F17: =IF($K17="","",IF(INDEX(BASELINE!$P$2:$P$3001,$K17)="","",INDEX(BASELINE!$P$2:$P$3001,$K17))) | G17: =IF($K17="","",IF(INDEX(BASELINE!$K$2:$K$3001,$K17)="","",INDEX(BASELINE!$K$2:$K$3001,$K17))) | H17: =IF($K17="","",IF(INDEX(BASELINE!$N$2:$N$3001,$K17)="","",INDEX(BASELINE!$N$2:$N$3001,$K17))) | I17: =IF($K17="","",IF(INDEX(BASELINE!$O$2:$O$3001,$K17)="","",INDEX(BASELINE!$O$2:$O$3001,$K17))) | J17: =IF($K17="","",IF(ISNUMBER(SEARCH("break",INDEX(BASELINE!$T$2:$T$3001,$K17)&"")),"SIM","")) | K17: =IF(9<=CALC!$D$1,MATCH(9,CALC!$B$2:$B$3001,0),"")
A18: =IF($K18="","",10) | B18: =IF($K18="","",IF(INDEX(BASELINE!$I$2:$I$3001,$K18)="","",INDEX(BASELINE!$I$2:$I$3001,$K18))) | C18: =IF($K18="","",IF(INDEX(BASELINE!$J$2:$J$3001,$K18)="","",INDEX(BASELINE!$J$2:$J$3001,$K18))) | D18: =IF($K18="","",IF(INDEX(BASELINE!$M$2:$M$3001,$K18)="","",INDEX(BASELINE!$M$2:$M$3001,$K18))) | E18: =IF($K18="","",IF(INDEX(BASELINE!$L$2:$L$3001,$K18)="","",INDEX(BASELINE!$L$2:$L$3001,$K18))) | F18: =IF($K18="","",IF(INDEX(BASELINE!$P$2:$P$3001,$K18)="","",INDEX(BASELINE!$P$2:$P$3001,$K18))) | G18: =IF($K18="","",IF(INDEX(BASELINE!$K$2:$K$3001,$K18)="","",INDEX(BASELINE!$K$2:$K$3001,$K18))) | H18: =IF($K18="","",IF(INDEX(BASELINE!$N$2:$N$3001,$K18)="","",INDEX(BASELINE!$N$2:$N$3001,$K18))) | I18: =IF($K18="","",IF(INDEX(BASELINE!$O$2:$O$3001,$K18)="","",INDEX(BASELINE!$O$2:$O$3001,$K18))) | J18: =IF($K18="","",IF(ISNUMBER(SEARCH("break",INDEX(BASELINE!$T$2:$T$3001,$K18)&"")),"SIM","")) | K18: =IF(10<=CALC!$D$1,MATCH(10,CALC!$B$2:$B$3001,0),"")
A19: =IF($K19="","",11) | B19: =IF($K19="","",IF(INDEX(BASELINE!$I$2:$I$3001,$K19)="","",INDEX(BASELINE!$I$2:$I$3001,$K19))) | C19: =IF($K19="","",IF(INDEX(BASELINE!$J$2:$J$3001,$K19)="","",INDEX(BASELINE!$J$2:$J$3001,$K19))) | D19: =IF($K19="","",IF(INDEX(BASELINE!$M$2:$M$3001,$K19)="","",INDEX(BASELINE!$M$2:$M$3001,$K19))) | E19: =IF($K19="","",IF(INDEX(BASELINE!$L$2:$L$3001,$K19)="","",INDEX(BASELINE!$L$2:$L$3001,$K19))) | F19: =IF($K19="","",IF(INDEX(BASELINE!$P$2:$P$3001,$K19)="","",INDEX(BASELINE!$P$2:$P$3001,$K19))) | G19: =IF($K19="","",IF(INDEX(BASELINE!$K$2:$K$3001,$K19)="","",INDEX(BASELINE!$K$2:$K$3001,$K19))) | H19: =IF($K19="","",IF(INDEX(BASELINE!$N$2:$N$3001,$K19)="","",INDEX(BASELINE!$N$2:$N$3001,$K19))) | I19: =IF($K19="","",IF(INDEX(BASELINE!$O$2:$O$3001,$K19)="","",INDEX(BASELINE!$O$2:$O$3001,$K19))) | J19: =IF($K19="","",IF(ISNUMBER(SEARCH("break",INDEX(BASELINE!$T$2:$T$3001,$K19)&"")),"SIM","")) | K19: =IF(11<=CALC!$D$1,MATCH(11,CALC!$B$2:$B$3001,0),"")
A20: =IF($K20="","",12) | B20: =IF($K20="","",IF(INDEX(BASELINE!$I$2:$I$3001,$K20)="","",INDEX(BASELINE!$I$2:$I$3001,$K20))) | C20: =IF($K20="","",IF(INDEX(BASELINE!$J$2:$J$3001,$K20)="","",INDEX(BASELINE!$J$2:$J$3001,$K20))) | D20: =IF($K20="","",IF(INDEX(BASELINE!$M$2:$M$3001,$K20)="","",INDEX(BASELINE!$M$2:$M$3001,$K20))) | E20: =IF($K20="","",IF(INDEX(BASELINE!$L$2:$L$3001,$K20)="","",INDEX(BASELINE!$L$2:$L$3001,$K20))) | F20: =IF($K20="","",IF(INDEX(BASELINE!$P$2:$P$3001,$K20)="","",INDEX(BASELINE!$P$2:$P$3001,$K20))) | G20: =IF($K20="","",IF(INDEX(BASELINE!$K$2:$K$3001,$K20)="","",INDEX(BASELINE!$K$2:$K$3001,$K20))) | H20: =IF($K20="","",IF(INDEX(BASELINE!$N$2:$N$3001,$K20)="","",INDEX(BASELINE!$N$2:$N$3001,$K20))) | I20: =IF($K20="","",IF(INDEX(BASELINE!$O$2:$O$3001,$K20)="","",INDEX(BASELINE!$O$2:$O$3001,$K20))) | J20: =IF($K20="","",IF(ISNUMBER(SEARCH("break",INDEX(BASELINE!$T$2:$T$3001,$K20)&"")),"SIM","")) | K20: =IF(12<=CALC!$D$1,MATCH(12,CALC!$B$2:$B$3001,0),"")
A21: =IF($K21="","",13) | B21: =IF($K21="","",IF(INDEX(BASELINE!$I$2:$I$3001,$K21)="","",INDEX(BASELINE!$I$2:$I$3001,$K21))) | C21: =IF($K21="","",IF(INDEX(BASELINE!$J$2:$J$3001,$K21)="","",INDEX(BASELINE!$J$2:$J$3001,$K21))) | D21: =IF($K21="","",IF(INDEX(BASELINE!$M$2:$M$3001,$K21)="","",INDEX(BASELINE!$M$2:$M$3001,$K21))) | E21: =IF($K21="","",IF(INDEX(BASELINE!$L$2:$L$3001,$K21)="","",INDEX(BASELINE!$L$2:$L$3001,$K21))) | F21: =IF($K21="","",IF(INDEX(BASELINE!$P$2:$P$3001,$K21)="","",INDEX(BASELINE!$P$2:$P$3001,$K21))) | G21: =IF($K21="","",IF(INDEX(BASELINE!$K$2:$K$3001,$K21)="","",INDEX(BASELINE!$K$2:$K$3001,$K21))) | H21: =IF($K21="","",IF(INDEX(BASELINE!$N$2:$N$3001,$K21)="","",INDEX(BASELINE!$N$2:$N$3001,$K21))) | I21: =IF($K21="","",IF(INDEX(BASELINE!$O$2:$O$3001,$K21)="","",INDEX(BASELINE!$O$2:$O$3001,$K21))) | J21: =IF($K21="","",IF(ISNUMBER(SEARCH("break",INDEX(BASELINE!$T$2:$T$3001,$K21)&"")),"SIM","")) | K21: =IF(13<=CALC!$D$1,MATCH(13,CALC!$B$2:$B$3001,0),"")
A22: =IF($K22="","",14) | B22: =IF($K22="","",IF(INDEX(BASELINE!$I$2:$I$3001,$K22)="","",INDEX(BASELINE!$I$2:$I$3001,$K22))) | C22: =IF($K22="","",IF(INDEX(BASELINE!$J$2:$J$3001,$K22)="","",INDEX(BASELINE!$J$2:$J$3001,$K22))) | D22: =IF($K22="","",IF(INDEX(BASELINE!$M$2:$M$3001,$K22)="","",INDEX(BASELINE!$M$2:$M$3001,$K22))) | E22: =IF($K22="","",IF(INDEX(BASELINE!$L$2:$L$3001,$K22)="","",INDEX(BASELINE!$L$2:$L$3001,$K22))) | F22: =IF($K22="","",IF(INDEX(BASELINE!$P$2:$P$3001,$K22)="","",INDEX(BASELINE!$P$2:$P$3001,$K22))) | G22: =IF($K22="","",IF(INDEX(BASELINE!$K$2:$K$3001,$K22)="","",INDEX(BASELINE!$K$2:$K$3001,$K22))) | H22: =IF($K22="","",IF(INDEX(BASELINE!$N$2:$N$3001,$K22)="","",INDEX(BASELINE!$N$2:$N$3001,$K22))) | I22: =IF($K22="","",IF(INDEX(BASELINE!$O$2:$O$3001,$K22)="","",INDEX(BASELINE!$O$2:$O$3001,$K22))) | J22: =IF($K22="","",IF(ISNUMBER(SEARCH("break",INDEX(BASELINE!$T$2:$T$3001,$K22)&"")),"SIM","")) | K22: =IF(14<=CALC!$D$1,MATCH(14,CALC!$B$2:$B$3001,0),"")
A23: =IF($K23="","",15) | B23: =IF($K23="","",IF(INDEX(BASELINE!$I$2:$I$3001,$K23)="","",INDEX(BASELINE!$I$2:$I$3001,$K23))) | C23: =IF($K23="","",IF(INDEX(BASELINE!$J$2:$J$3001,$K23)="","",INDEX(BASELINE!$J$2:$J$3001,$K23))) | D23: =IF($K23="","",IF(INDEX(BASELINE!$M$2:$M$3001,$K23)="","",INDEX(BASELINE!$M$2:$M$3001,$K23))) | E23: =IF($K23="","",IF(INDEX(BASELINE!$L$2:$L$3001,$K23)="","",INDEX(BASELINE!$L$2:$L$3001,$K23))) | F23: =IF($K23="","",IF(INDEX(BASELINE!$P$2:$P$3001,$K23)="","",INDEX(BASELINE!$P$2:$P$3001,$K23))) | G23: =IF($K23="","",IF(INDEX(BASELINE!$K$2:$K$3001,$K23)="","",INDEX(BASELINE!$K$2:$K$3001,$K23))) | H23: =IF($K23="","",IF(INDEX(BASELINE!$N$2:$N$3001,$K23)="","",INDEX(BASELINE!$N$2:$N$3001,$K23))) | I23: =IF($K23="","",IF(INDEX(BASELINE!$O$2:$O$3001,$K23)="","",INDEX(BASELINE!$O$2:$O$3001,$K23))) | J23: =IF($K23="","",IF(ISNUMBER(SEARCH("break",INDEX(BASELINE!$T$2:$T$3001,$K23)&"")),"SIM","")) | K23: =IF(15<=CALC!$D$1,MATCH(15,CALC!$B$2:$B$3001,0),"")
A24: =IF($K24="","",16) | B24: =IF($K24="","",IF(INDEX(BASELINE!$I$2:$I$3001,$K24)="","",INDEX(BASELINE!$I$2:$I$3001,$K24))) | C24: =IF($K24="","",IF(INDEX(BASELINE!$J$2:$J$3001,$K24)="","",INDEX(BASELINE!$J$2:$J$3001,$K24))) | D24: =IF($K24="","",IF(INDEX(BASELINE!$M$2:$M$3001,$K24)="","",INDEX(BASELINE!$M$2:$M$3001,$K24))) | E24: =IF($K24="","",IF(INDEX(BASELINE!$L$2:$L$3001,$K24)="","",INDEX(BASELINE!$L$2:$L$3001,$K24))) | F24: =IF($K24="","",IF(INDEX(BASELINE!$P$2:$P$3001,$K24)="","",INDEX(BASELINE!$P$2:$P$3001,$K24))) | G24: =IF($K24="","",IF(INDEX(BASELINE!$K$2:$K$3001,$K24)="","",INDEX(BASELINE!$K$2:$K$3001,$K24))) | H24: =IF($K24="","",IF(INDEX(BASELINE!$N$2:$N$3001,$K24)="","",INDEX(BASELINE!$N$2:$N$3001,$K24))) | I24: =IF($K24="","",IF(INDEX(BASELINE!$O$2:$O$3001,$K24)="","",INDEX(BASELINE!$O$2:$O$3001,$K24))) | J24: =IF($K24="","",IF(ISNUMBER(SEARCH("break",INDEX(BASELINE!$T$2:$T$3001,$K24)&"")),"SIM","")) | K24: =IF(16<=CALC!$D$1,MATCH(16,CALC!$B$2:$B$3001,0),"")
A25: =IF($K25="","",17) | B25: =IF($K25="","",IF(INDEX(BASELINE!$I$2:$I$3001,$K25)="","",INDEX(BASELINE!$I$2:$I$3001,$K25))) | C25: =IF($K25="","",IF(INDEX(BASELINE!$J$2:$J$3001,$K25)="","",INDEX(BASELINE!$J$2:$J$3001,$K25))) | D25: =IF($K25="","",IF(INDEX(BASELINE!$M$2:$M$3001,$K25)="","",INDEX(BASELINE!$M$2:$M$3001,$K25))) | E25: =IF($K25="","",IF(INDEX(BASELINE!$L$2:$L$3001,$K25)="","",INDEX(BASELINE!$L$2:$L$3001,$K25))) | F25: =IF($K25="","",IF(INDEX(BASELINE!$P$2:$P$3001,$K25)="","",INDEX(BASELINE!$P$2:$P$3001,$K25))) | G25: =IF($K25="","",IF(INDEX(BASELINE!$K$2:$K$3001,$K25)="","",INDEX(BASELINE!$K$2:$K$3001,$K25))) | H25: =IF($K25="","",IF(INDEX(BASELINE!$N$2:$N$3001,$K25)="","",INDEX(BASELINE!$N$2:$N$3001,$K25))) | I25: =IF($K25="","",IF(INDEX(BASELINE!$O$2:$O$3001,$K25)="","",INDEX(BASELINE!$O$2:$O$3001,$K25))) | J25: =IF($K25="","",IF(ISNUMBER(SEARCH("break",INDEX(BASELINE!$T$2:$T$3001,$K25)&"")),"SIM","")) | K25: =IF(17<=CALC!$D$1,MATCH(17,CALC!$B$2:$B$3001,0),"")
A26: =IF($K26="","",18) | B26: =IF($K26="","",IF(INDEX(BASELINE!$I$2:$I$3001,$K26)="","",INDEX(BASELINE!$I$2:$I$3001,$K26))) | C26: =IF($K26="","",IF(INDEX(BASELINE!$J$2:$J$3001,$K26)="","",INDEX(BASELINE!$J$2:$J$3001,$K26))) | D26: =IF($K26="","",IF(INDEX(BASELINE!$M$2:$M$3001,$K26)="","",INDEX(BASELINE!$M$2:$M$3001,$K26))) | E26: =IF($K26="","",IF(INDEX(BASELINE!$L$2:$L$3001,$K26)="","",INDEX(BASELINE!$L$2:$L$3001,$K26))) | F26: =IF($K26="","",IF(INDEX(BASELINE!$P$2:$P$3001,$K26)="","",INDEX(BASELINE!$P$2:$P$3001,$K26))) | G26: =IF($K26="","",IF(INDEX(BASELINE!$K$2:$K$3001,$K26)="","",INDEX(BASELINE!$K$2:$K$3001,$K26))) | H26: =IF($K26="","",IF(INDEX(BASELINE!$N$2:$N$3001,$K26)="","",INDEX(BASELINE!$N$2:$N$3001,$K26))) | I26: =IF($K26="","",IF(INDEX(BASELINE!$O$2:$O$3001,$K26)="","",INDEX(BASELINE!$O$2:$O$3001,$K26))) | J26: =IF($K26="","",IF(ISNUMBER(SEARCH("break",INDEX(BASELINE!$T$2:$T$3001,$K26)&"")),"SIM","")) | K26: =IF(18<=CALC!$D$1,MATCH(18,CALC!$B$2:$B$3001,0),"")
A27: =IF($K27="","",19) | B27: =IF($K27="","",IF(INDEX(BASELINE!$I$2:$I$3001,$K27)="","",INDEX(BASELINE!$I$2:$I$3001,$K27))) | C27: =IF($K27="","",IF(INDEX(BASELINE!$J$2:$J$3001,$K27)="","",INDEX(BASELINE!$J$2:$J$3001,$K27))) | D27: =IF($K27="","",IF(INDEX(BASELINE!$M$2:$M$3001,$K27)="","",INDEX(BASELINE!$M$2:$M$3001,$K27))) | E27: =IF($K27="","",IF(INDEX(BASELINE!$L$2:$L$3001,$K27)="","",INDEX(BASELINE!$L$2:$L$3001,$K27))) | F27: =IF($K27="","",IF(INDEX(BASELINE!$P$2:$P$3001,$K27)="","",INDEX(BASELINE!$P$2:$P$3001,$K27))) | G27: =IF($K27="","",IF(INDEX(BASELINE!$K$2:$K$3001,$K27)="","",INDEX(BASELINE!$K$2:$K$3001,$K27))) | H27: =IF($K27="","",IF(INDEX(BASELINE!$N$2:$N$3001,$K27)="","",INDEX(BASELINE!$N$2:$N$3001,$K27))) | I27: =IF($K27="","",IF(INDEX(BASELINE!$O$2:$O$3001,$K27)="","",INDEX(BASELINE!$O$2:$O$3001,$K27))) | J27: =IF($K27="","",IF(ISNUMBER(SEARCH("break",INDEX(BASELINE!$T$2:$T$3001,$K27)&"")),"SIM","")) | K27: =IF(19<=CALC!$D$1,MATCH(19,CALC!$B$2:$B$3001,0),"")
A28: =IF($K28="","",20) | B28: =IF($K28="","",IF(INDEX(BASELINE!$I$2:$I$3001,$K28)="","",INDEX(BASELINE!$I$2:$I$3001,$K28))) | C28: =IF($K28="","",IF(INDEX(BASELINE!$J$2:$J$3001,$K28)="","",INDEX(BASELINE!$J$2:$J$3001,$K28))) | D28: =IF($K28="","",IF(INDEX(BASELINE!$M$2:$M$3001,$K28)="","",INDEX(BASELINE!$M$2:$M$3001,$K28))) | E28: =IF($K28="","",IF(INDEX(BASELINE!$L$2:$L$3001,$K28)="","",INDEX(BASELINE!$L$2:$L$3001,$K28))) | F28: =IF($K28="","",IF(INDEX(BASELINE!$P$2:$P$3001,$K28)="","",INDEX(BASELINE!$P$2:$P$3001,$K28))) | G28: =IF($K28="","",IF(INDEX(BASELINE!$K$2:$K$3001,$K28)="","",INDEX(BASELINE!$K$2:$K$3001,$K28))) | H28: =IF($K28="","",IF(INDEX(BASELINE!$N$2:$N$3001,$K28)="","",INDEX(BASELINE!$N$2:$N$3001,$K28))) | I28: =IF($K28="","",IF(INDEX(BASELINE!$O$2:$O$3001,$K28)="","",INDEX(BASELINE!$O$2:$O$3001,$K28))) | J28: =IF($K28="","",IF(ISNUMBER(SEARCH("break",INDEX(BASELINE!$T$2:$T$3001,$K28)&"")),"SIM","")) | K28: =IF(20<=CALC!$D$1,MATCH(20,CALC!$B$2:$B$3001,0),"")
A29: =IF($K29="","",21) | B29: =IF($K29="","",IF(INDEX(BASELINE!$I$2:$I$3001,$K29)="","",INDEX(BASELINE!$I$2:$I$3001,$K29))) | C29: =IF($K29="","",IF(INDEX(BASELINE!$J$2:$J$3001,$K29)="","",INDEX(BASELINE!$J$2:$J$3001,$K29))) | D29: =IF($K29="","",IF(INDEX(BASELINE!$M$2:$M$3001,$K29)="","",INDEX(BASELINE!$M$2:$M$3001,$K29))) | E29: =IF($K29="","",IF(INDEX(BASELINE!$L$2:$L$3001,$K29)="","",INDEX(BASELINE!$L$2:$L$3001,$K29))) | F29: =IF($K29="","",IF(INDEX(BASELINE!$P$2:$P$3001,$K29)="","",INDEX(BASELINE!$P$2:$P$3001,$K29))) | G29: =IF($K29="","",IF(INDEX(BASELINE!$K$2:$K$3001,$K29)="","",INDEX(BASELINE!$K$2:$K$3001,$K29))) | H29: =IF($K29="","",IF(INDEX(BASELINE!$N$2:$N$3001,$K29)="","",INDEX(BASELINE!$N$2:$N$3001,$K29))) | I29: =IF($K29="","",IF(INDEX(BASELINE!$O$2:$O$3001,$K29)="","",INDEX(BASELINE!$O$2:$O$3001,$K29))) | J29: =IF($K29="","",IF(ISNUMBER(SEARCH("break",INDEX(BASELINE!$T$2:$T$3001,$K29)&"")),"SIM","")) | K29: =IF(21<=CALC!$D$1,MATCH(21,CALC!$B$2:$B$3001,0),"")
A30: =IF($K30="","",22) | B30: =IF($K30="","",IF(INDEX(BASELINE!$I$2:$I$3001,$K30)="","",INDEX(BASELINE!$I$2:$I$3001,$K30))) | C30: =IF($K30="","",IF(INDEX(BASELINE!$J$2:$J$3001,$K30)="","",INDEX(BASELINE!$J$2:$J$3001,$K30))) | D30: =IF($K30="","",IF(INDEX(BASELINE!$M$2:$M$3001,$K30)="","",INDEX(BASELINE!$M$2:$M$3001,$K30))) | E30: =IF($K30="","",IF(INDEX(BASELINE!$L$2:$L$3001,$K30)="","",INDEX(BASELINE!$L$2:$L$3001,$K30))) | F30: =IF($K30="","",IF(INDEX(BASELINE!$P$2:$P$3001,$K30)="","",INDEX(BASELINE!$P$2:$P$3001,$K30))) | G30: =IF($K30="","",IF(INDEX(BASELINE!$K$2:$K$3001,$K30)="","",INDEX(BASELINE!$K$2:$K$3001,$K30))) | H30: =IF($K30="","",IF(INDEX(BASELINE!$N$2:$N$3001,$K30)="","",INDEX(BASELINE!$N$2:$N$3001,$K30))) | I30: =IF($K30="","",IF(INDEX(BASELINE!$O$2:$O$3001,$K30)="","",INDEX(BASELINE!$O$2:$O$3001,$K30))) | J30: =IF($K30="","",IF(ISNUMBER(SEARCH("break",INDEX(BASELINE!$T$2:$T$3001,$K30)&"")),"SIM","")) | K30: =IF(22<=CALC!$D$1,MATCH(22,CALC!$B$2:$B$3001,0),"")
A31: =IF($K31="","",23) | B31: =IF($K31="","",IF(INDEX(BASELINE!$I$2:$I$3001,$K31)="","",INDEX(BASELINE!$I$2:$I$3001,$K31))) | C31: =IF($K31="","",IF(INDEX(BASELINE!$J$2:$J$3001,$K31)="","",INDEX(BASELINE!$J$2:$J$3001,$K31))) | D31: =IF($K31="","",IF(INDEX(BASELINE!$M$2:$M$3001,$K31)="","",INDEX(BASELINE!$M$2:$M$3001,$K31))) | E31: =IF($K31="","",IF(INDEX(BASELINE!$L$2:$L$3001,$K31)="","",INDEX(BASELINE!$L$2:$L$3001,$K31))) | F31: =IF($K31="","",IF(INDEX(BASELINE!$P$2:$P$3001,$K31)="","",INDEX(BASELINE!$P$2:$P$3001,$K31))) | G31: =IF($K31="","",IF(INDEX(BASELINE!$K$2:$K$3001,$K31)="","",INDEX(BASELINE!$K$2:$K$3001,$K31))) | H31: =IF($K31="","",IF(INDEX(BASELINE!$N$2:$N$3001,$K31)="","",INDEX(BASELINE!$N$2:$N$3001,$K31))) | I31: =IF($K31="","",IF(INDEX(BASELINE!$O$2:$O$3001,$K31)="","",INDEX(BASELINE!$O$2:$O$3001,$K31))) | J31: =IF($K31="","",IF(ISNUMBER(SEARCH("break",INDEX(BASELINE!$T$2:$T$3001,$K31)&"")),"SIM","")) | K31: =IF(23<=CALC!$D$1,MATCH(23,CALC!$B$2:$B$3001,0),"")
A32: =IF($K32="","",24) | B32: =IF($K32="","",IF(INDEX(BASELINE!$I$2:$I$3001,$K32)="","",INDEX(BASELINE!$I$2:$I$3001,$K32))) | C32: =IF($K32="","",IF(INDEX(BASELINE!$J$2:$J$3001,$K32)="","",INDEX(BASELINE!$J$2:$J$3001,$K32))) | D32: =IF($K32="","",IF(INDEX(BASELINE!$M$2:$M$3001,$K32)="","",INDEX(BASELINE!$M$2:$M$3001,$K32))) | E32: =IF($K32="","",IF(INDEX(BASELINE!$L$2:$L$3001,$K32)="","",INDEX(BASELINE!$L$2:$L$3001,$K32))) | F32: =IF($K32="","",IF(INDEX(BASELINE!$P$2:$P$3001,$K32)="","",INDEX(BASELINE!$P$2:$P$3001,$K32))) | G32: =IF($K32="","",IF(INDEX(BASELINE!$K$2:$K$3001,$K32)="","",INDEX(BASELINE!$K$2:$K$3001,$K32))) | H32: =IF($K32="","",IF(INDEX(BASELINE!$N$2:$N$3001,$K32)="","",INDEX(BASELINE!$N$2:$N$3001,$K32))) | I32: =IF($K32="","",IF(INDEX(BASELINE!$O$2:$O$3001,$K32)="","",INDEX(BASELINE!$O$2:$O$3001,$K32))) | J32: =IF($K32="","",IF(ISNUMBER(SEARCH("break",INDEX(BASELINE!$T$2:$T$3001,$K32)&"")),"SIM","")) | K32: =IF(24<=CALC!$D$1,MATCH(24,CALC!$B$2:$B$3001,0),"")
A33: =IF($K33="","",25) | B33: =IF($K33="","",IF(INDEX(BASELINE!$I$2:$I$3001,$K33)="","",INDEX(BASELINE!$I$2:$I$3001,$K33))) | C33: =IF($K33="","",IF(INDEX(BASELINE!$J$2:$J$3001,$K33)="","",INDEX(BASELINE!$J$2:$J$3001,$K33))) | D33: =IF($K33="","",IF(INDEX(BASELINE!$M$2:$M$3001,$K33)="","",INDEX(BASELINE!$M$2:$M$3001,$K33))) | E33: =IF($K33="","",IF(INDEX(BASELINE!$L$2:$L$3001,$K33)="","",INDEX(BASELINE!$L$2:$L$3001,$K33))) | F33: =IF($K33="","",IF(INDEX(BASELINE!$P$2:$P$3001,$K33)="","",INDEX(BASELINE!$P$2:$P$3001,$K33))) | G33: =IF($K33="","",IF(INDEX(BASELINE!$K$2:$K$3001,$K33)="","",INDEX(BASELINE!$K$2:$K$3001,$K33))) | H33: =IF($K33="","",IF(INDEX(BASELINE!$N$2:$N$3001,$K33)="","",INDEX(BASELINE!$N$2:$N$3001,$K33))) | I33: =IF($K33="","",IF(INDEX(BASELINE!$O$2:$O$3001,$K33)="","",INDEX(BASELINE!$O$2:$O$3001,$K33))) | J33: =IF($K33="","",IF(ISNUMBER(SEARCH("break",INDEX(BASELINE!$T$2:$T$3001,$K33)&"")),"SIM","")) | K33: =IF(25<=CALC!$D$1,MATCH(25,CALC!$B$2:$B$3001,0),"")
A34: =IF($K34="","",26) | B34: =IF($K34="","",IF(INDEX(BASELINE!$I$2:$I$3001,$K34)="","",INDEX(BASELINE!$I$2:$I$3001,$K34))) | C34: =IF($K34="","",IF(INDEX(BASELINE!$J$2:$J$3001,$K34)="","",INDEX(BASELINE!$J$2:$J$3001,$K34))) | D34: =IF($K34="","",IF(INDEX(BASELINE!$M$2:$M$3001,$K34)="","",INDEX(BASELINE!$M$2:$M$3001,$K34))) | E34: =IF($K34="","",IF(INDEX(BASELINE!$L$2:$L$3001,$K34)="","",INDEX(BASELINE!$L$2:$L$3001,$K34))) | F34: =IF($K34="","",IF(INDEX(BASELINE!$P$2:$P$3001,$K34)="","",INDEX(BASELINE!$P$2:$P$3001,$K34))) | G34: =IF($K34="","",IF(INDEX(BASELINE!$K$2:$K$3001,$K34)="","",INDEX(BASELINE!$K$2:$K$3001,$K34))) | H34: =IF($K34="","",IF(INDEX(BASELINE!$N$2:$N$3001,$K34)="","",INDEX(BASELINE!$N$2:$N$3001,$K34))) | I34: =IF($K34="","",IF(INDEX(BASELINE!$O$2:$O$3001,$K34)="","",INDEX(BASELINE!$O$2:$O$3001,$K34))) | J34: =IF($K34="","",IF(ISNUMBER(SEARCH("break",INDEX(BASELINE!$T$2:$T$3001,$K34)&"")),"SIM","")) | K34: =IF(26<=CALC!$D$1,MATCH(26,CALC!$B$2:$B$3001,0),"")
A35: =IF($K35="","",27) | B35: =IF($K35="","",IF(INDEX(BASELINE!$I$2:$I$3001,$K35)="","",INDEX(BASELINE!$I$2:$I$3001,$K35))) | C35: =IF($K35="","",IF(INDEX(BASELINE!$J$2:$J$3001,$K35)="","",INDEX(BASELINE!$J$2:$J$3001,$K35))) | D35: =IF($K35="","",IF(INDEX(BASELINE!$M$2:$M$3001,$K35)="","",INDEX(BASELINE!$M$2:$M$3001,$K35))) | E35: =IF($K35="","",IF(INDEX(BASELINE!$L$2:$L$3001,$K35)="","",INDEX(BASELINE!$L$2:$L$3001,$K35))) | F35: =IF($K35="","",IF(INDEX(BASELINE!$P$2:$P$3001,$K35)="","",INDEX(BASELINE!$P$2:$P$3001,$K35))) | G35: =IF($K35="","",IF(INDEX(BASELINE!$K$2:$K$3001,$K35)="","",INDEX(BASELINE!$K$2:$K$3001,$K35))) | H35: =IF($K35="","",IF(INDEX(BASELINE!$N$2:$N$3001,$K35)="","",INDEX(BASELINE!$N$2:$N$3001,$K35))) | I35: =IF($K35="","",IF(INDEX(BASELINE!$O$2:$O$3001,$K35)="","",INDEX(BASELINE!$O$2:$O$3001,$K35))) | J35: =IF($K35="","",IF(ISNUMBER(SEARCH("break",INDEX(BASELINE!$T$2:$T$3001,$K35)&"")),"SIM","")) | K35: =IF(27<=CALC!$D$1,MATCH(27,CALC!$B$2:$B$3001,0),"")
A36: =IF($K36="","",28) | B36: =IF($K36="","",IF(INDEX(BASELINE!$I$2:$I$3001,$K36)="","",INDEX(BASELINE!$I$2:$I$3001,$K36))) | C36: =IF($K36="","",IF(INDEX(BASELINE!$J$2:$J$3001,$K36)="","",INDEX(BASELINE!$J$2:$J$3001,$K36))) | D36: =IF($K36="","",IF(INDEX(BASELINE!$M$2:$M$3001,$K36)="","",INDEX(BASELINE!$M$2:$M$3001,$K36))) | E36: =IF($K36="","",IF(INDEX(BASELINE!$L$2:$L$3001,$K36)="","",INDEX(BASELINE!$L$2:$L$3001,$K36))) | F36: =IF($K36="","",IF(INDEX(BASELINE!$P$2:$P$3001,$K36)="","",INDEX(BASELINE!$P$2:$P$3001,$K36))) | G36: =IF($K36="","",IF(INDEX(BASELINE!$K$2:$K$3001,$K36)="","",INDEX(BASELINE!$K$2:$K$3001,$K36))) | H36: =IF($K36="","",IF(INDEX(BASELINE!$N$2:$N$3001,$K36)="","",INDEX(BASELINE!$N$2:$N$3001,$K36))) | I36: =IF($K36="","",IF(INDEX(BASELINE!$O$2:$O$3001,$K36)="","",INDEX(BASELINE!$O$2:$O$3001,$K36))) | J36: =IF($K36="","",IF(ISNUMBER(SEARCH("break",INDEX(BASELINE!$T$2:$T$3001,$K36)&"")),"SIM","")) | K36: =IF(28<=CALC!$D$1,MATCH(28,CALC!$B$2:$B$3001,0),"")
A37: =IF($K37="","",29) | B37: =IF($K37="","",IF(INDEX(BASELINE!$I$2:$I$3001,$K37)="","",INDEX(BASELINE!$I$2:$I$3001,$K37))) | C37: =IF($K37="","",IF(INDEX(BASELINE!$J$2:$J$3001,$K37)="","",INDEX(BASELINE!$J$2:$J$3001,$K37))) | D37: =IF($K37="","",IF(INDEX(BASELINE!$M$2:$M$3001,$K37)="","",INDEX(BASELINE!$M$2:$M$3001,$K37))) | E37: =IF($K37="","",IF(INDEX(BASELINE!$L$2:$L$3001,$K37)="","",INDEX(BASELINE!$L$2:$L$3001,$K37))) | F37: =IF($K37="","",IF(INDEX(BASELINE!$P$2:$P$3001,$K37)="","",INDEX(BASELINE!$P$2:$P$3001,$K37))) | G37: =IF($K37="","",IF(INDEX(BASELINE!$K$2:$K$3001,$K37)="","",INDEX(BASELINE!$K$2:$K$3001,$K37))) | H37: =IF($K37="","",IF(INDEX(BASELINE!$N$2:$N$3001,$K37)="","",INDEX(BASELINE!$N$2:$N$3001,$K37))) | I37: =IF($K37="","",IF(INDEX(BASELINE!$O$2:$O$3001,$K37)="","",INDEX(BASELINE!$O$2:$O$3001,$K37))) | J37: =IF($K37="","",IF(ISNUMBER(SEARCH("break",INDEX(BASELINE!$T$2:$T$3001,$K37)&"")),"SIM","")) | K37: =IF(29<=CALC!$D$1,MATCH(29,CALC!$B$2:$B$3001,0),"")
A38: =IF($K38="","",30) | B38: =IF($K38="","",IF(INDEX(BASELINE!$I$2:$I$3001,$K38)="","",INDEX(BASELINE!$I$2:$I$3001,$K38))) | C38: =IF($K38="","",IF(INDEX(BASELINE!$J$2:$J$3001,$K38)="","",INDEX(BASELINE!$J$2:$J$3001,$K38))) | D38: =IF($K38="","",IF(INDEX(BASELINE!$M$2:$M$3001,$K38)="","",INDEX(BASELINE!$M$2:$M$3001,$K38))) | E38: =IF($K38="","",IF(INDEX(BASELINE!$L$2:$L$3001,$K38)="","",INDEX(BASELINE!$L$2:$L$3001,$K38))) | F38: =IF($K38="","",IF(INDEX(BASELINE!$P$2:$P$3001,$K38)="","",INDEX(BASELINE!$P$2:$P$3001,$K38))) | G38: =IF($K38="","",IF(INDEX(BASELINE!$K$2:$K$3001,$K38)="","",INDEX(BASELINE!$K$2:$K$3001,$K38))) | H38: =IF($K38="","",IF(INDEX(BASELINE!$N$2:$N$3001,$K38)="","",INDEX(BASELINE!$N$2:$N$3001,$K38))) | I38: =IF($K38="","",IF(INDEX(BASELINE!$O$2:$O$3001,$K38)="","",INDEX(BASELINE!$O$2:$O$3001,$K38))) | J38: =IF($K38="","",IF(ISNUMBER(SEARCH("break",INDEX(BASELINE!$T$2:$T$3001,$K38)&"")),"SIM","")) | K38: =IF(30<=CALC!$D$1,MATCH(30,CALC!$B$2:$B$3001,0),"")
A39: =IF($K39="","",31) | B39: =IF($K39="","",IF(INDEX(BASELINE!$I$2:$I$3001,$K39)="","",INDEX(BASELINE!$I$2:$I$3001,$K39))) | C39: =IF($K39="","",IF(INDEX(BASELINE!$J$2:$J$3001,$K39)="","",INDEX(BASELINE!$J$2:$J$3001,$K39))) | D39: =IF($K39="","",IF(INDEX(BASELINE!$M$2:$M$3001,$K39)="","",INDEX(BASELINE!$M$2:$M$3001,$K39))) | E39: =IF($K39="","",IF(INDEX(BASELINE!$L$2:$L$3001,$K39)="","",INDEX(BASELINE!$L$2:$L$3001,$K39))) | F39: =IF($K39="","",IF(INDEX(BASELINE!$P$2:$P$3001,$K39)="","",INDEX(BASELINE!$P$2:$P$3001,$K39))) | G39: =IF($K39="","",IF(INDEX(BASELINE!$K$2:$K$3001,$K39)="","",INDEX(BASELINE!$K$2:$K$3001,$K39))) | H39: =IF($K39="","",IF(INDEX(BASELINE!$N$2:$N$3001,$K39)="","",INDEX(BASELINE!$N$2:$N$3001,$K39))) | I39: =IF($K39="","",IF(INDEX(BASELINE!$O$2:$O$3001,$K39)="","",INDEX(BASELINE!$O$2:$O$3001,$K39))) | J39: =IF($K39="","",IF(ISNUMBER(SEARCH("break",INDEX(BASELINE!$T$2:$T$3001,$K39)&"")),"SIM","")) | K39: =IF(31<=CALC!$D$1,MATCH(31,CALC!$B$2:$B$3001,0),"")
A40: =IF($K40="","",32) | B40: =IF($K40="","",IF(INDEX(BASELINE!$I$2:$I$3001,$K40)="","",INDEX(BASELINE!$I$2:$I$3001,$K40))) | C40: =IF($K40="","",IF(INDEX(BASELINE!$J$2:$J$3001,$K40)="","",INDEX(BASELINE!$J$2:$J$3001,$K40))) | D40: =IF($K40="","",IF(INDEX(BASELINE!$M$2:$M$3001,$K40)="","",INDEX(BASELINE!$M$2:$M$3001,$K40))) | E40: =IF($K40="","",IF(INDEX(BASELINE!$L$2:$L$3001,$K40)="","",INDEX(BASELINE!$L$2:$L$3001,$K40))) | F40: =IF($K40="","",IF(INDEX(BASELINE!$P$2:$P$3001,$K40)="","",INDEX(BASELINE!$P$2:$P$3001,$K40))) | G40: =IF($K40="","",IF(INDEX(BASELINE!$K$2:$K$3001,$K40)="","",INDEX(BASELINE!$K$2:$K$3001,$K40))) | H40: =IF($K40="","",IF(INDEX(BASELINE!$N$2:$N$3001,$K40)="","",INDEX(BASELINE!$N$2:$N$3001,$K40))) | I40: =IF($K40="","",IF(INDEX(BASELINE!$O$2:$O$3001,$K40)="","",INDEX(BASELINE!$O$2:$O$3001,$K40))) | J40: =IF($K40="","",IF(ISNUMBER(SEARCH("break",INDEX(BASELINE!$T$2:$T$3001,$K40)&"")),"SIM","")) | K40: =IF(32<=CALC!$D$1,MATCH(32,CALC!$B$2:$B$3001,0),"")
A41: =IF($K41="","",33) | B41: =IF($K41="","",IF(INDEX(BASELINE!$I$2:$I$3001,$K41)="","",INDEX(BASELINE!$I$2:$I$3001,$K41))) | C41: =IF($K41="","",IF(INDEX(BASELINE!$J$2:$J$3001,$K41)="","",INDEX(BASELINE!$J$2:$J$3001,$K41))) | D41: =IF($K41="","",IF(INDEX(BASELINE!$M$2:$M$3001,$K41)="","",INDEX(BASELINE!$M$2:$M$3001,$K41))) | E41: =IF($K41="","",IF(INDEX(BASELINE!$L$2:$L$3001,$K41)="","",INDEX(BASELINE!$L$2:$L$3001,$K41))) | F41: =IF($K41="","",IF(INDEX(BASELINE!$P$2:$P$3001,$K41)="","",INDEX(BASELINE!$P$2:$P$3001,$K41))) | G41: =IF($K41="","",IF(INDEX(BASELINE!$K$2:$K$3001,$K41)="","",INDEX(BASELINE!$K$2:$K$3001,$K41))) | H41: =IF($K41="","",IF(INDEX(BASELINE!$N$2:$N$3001,$K41)="","",INDEX(BASELINE!$N$2:$N$3001,$K41))) | I41: =IF($K41="","",IF(INDEX(BASELINE!$O$2:$O$3001,$K41)="","",INDEX(BASELINE!$O$2:$O$3001,$K41))) | J41: =IF($K41="","",IF(ISNUMBER(SEARCH("break",INDEX(BASELINE!$T$2:$T$3001,$K41)&"")),"SIM","")) | K41: =IF(33<=CALC!$D$1,MATCH(33,CALC!$B$2:$B$3001,0),"")
...

Sheet COMO USAR
B2: COMO ATUALIZAR TODO DIA
B3: 1 | C3: Na aba BASELINE, apague os dados antigos (linha 2 em diante) e cole a exportação atualizada nas colunas A:T, mantendo a ordem das colunas.
B4: 2 | C4: Na aba SIMOPS, confira a data em D3 (padrão: amanhã). Para outro dia, digite a data.
B5: 3 | C5: Pronto: a lista, os HH e as marcações se atualizam sozinhos. Imprima ou exporte em PDF para a reunião.
B7: REGRAS USADAS (por operação)
B8: Entra na lista | C8: Data oficial = coluna 'Reprogramado' (se preenchida com data); senão, 'Data Prog.'. Entra a operação cuja data oficial é igual à data de execução (D3). Ordens ENCERRADAS ficam sempre de fora.
B9: BREAK-IN | C9: Palavra 'break' na coluna Comentários.
B11: OBSERVAÇÕES
B12: Colunas usadas | C12: Reprogramado (se existir, pelo nome do cabeçalho) e E Data Prog., I Ordem, J Operação, K Cen.trab., L Txt. operação, M Texto breve, N Local, O Denominação LI, P Trabalho (HH), T Comentários, D Status.
B13: Capacidade | C13: Até 3.000 linhas na BASELINE e 150 operações por dia na lista SIMOPS.
B14: Aba CALC | C14: Auxiliar (oculta). Não editar.

Sheet BASELINE
B1: x | C1: Ordem | D1: Status | E1: Data Prog. | F1: P. | G1: C. | H1: Data planejada | I1: Ordem | J1: Operação | K1: Cen.trab.operação | L1: Txt.breve operação | M1: Texto breve | N1: Local de instalação | O1: Denominação do LI | P1: Trabalho | Q1: Status do usuario | R1: Tipo de Atividade | S1: Conclusão Desejada | T1: Comentários
A2: INS | B2: 434992210 | C2: 4349922 | D2: ABERTA | E2: 46325 | F2: 4 | G2: 2 | I2: 4349922 | J2: 10 | K2: INS | L2: Verificar as pressões hidráulicas | M2: Checagem do sistema hidráulico K60E | N2: 1349-73MA001 | P2: 3 | Q2: VEND | R2: Z12 | S2: 46378
A3: INS | B3: 434992220 | C3: 4349922 | D3: ABERTA | E3: 46325 | F3: 4 | G3: 2 | I3: 4349922 | J3: 20 | K3: INS | L3: Ajustar as pressões hidráulicas | M3: Checagem do sistema hidráulico K60E | N3: 1349-73MA001 | P3: 3 | Q3: VEND | R3: Z12 | S3: 46378
A4: AUT | B4: 434992310 | C4: 4349923 | D4: ABERTA | E4: 46326 | F4: 4 | G4: 2 | I4: 4349923 | J4: 10 | K4: AUT | L4: Inspeção no sistema hidráulico | M4: Checagem do sistema hidráulico K60W | N4: 1349-73MA002 | P4: 5 | Q4: VEND | R4: Z12 | S4: 46378
A5: AUT | B5: 435007110 | C5: 4350071 | D5: ABERTA | E5: 46319 | F5: 4 | G5: 2 | I5: 4350071 | J5: 10 | K5: AUT | L5: troubleshooting | M5: Camera Visible/Thermal com avaria | N5: 1349-86RCN1004 | P5: 5 | Q5: DPRO | R5: Z12 | S5: 46319
A6: INT | B6: 428524310 | C6: 4285243 | D6: ENCERRADA | E6: 46317 | F6: 6 | G6: 3 | I6: 4285243 | J6: 10 | K6: INT | L6: Medidor de espessura do SPIE | M6: Medidor de espessura do SPIE | N6: 1349 | P6: 0 | Q6: AMAT | R6: Z07 | S6: 46317
A7: MAR | B7: 435552810 | C7: 4355528 | D7: LIBERADA | E7: 46312 | F7: 4 | G7: 1 | I7: 4355528 | J7: 10 | K7: MAR | L7: Check do cilindro de ar | M7: Air Starter Baleeira 1 c/ pressão baixa | N7: 1349-76SA001 | P7: 1 | Q7: DPRO | R7: Z12 | S7: 46312
A8: MAR | B8: 435552820 | C8: 4355528 | D8: LIBERADA | E8: 46312 | F8: 4 | G8: 1 | I8: 4355528 | J8: 20 | K8: MAR | L8: Trocar o cilindro por um novo | M8: Air Starter Baleeira 1 c/ pressão baixa | N8: 1349-76SA001 | P8: 2 | Q8: DPRO | R8: Z12 | S8: 46312
A9: AUT | B9: 428816410 | C9: 4288164 | D9: ENCERRADA | E9: 46323 | F9: 6 | G9: 3 | I9: 4288164 | J9: 10 | K9: POMAUT | L9: 77FY5514 Pressure Ctrl Damper C/ avaria | M9: 77FY5514 Pressure Ctrl Damper C/ avaria | N9: 1349-77FY5514 | P9: 4 | Q9: DPRO | R9: Z12 | S9: 46323
A10: AUT | B10: 428479910 | C10: 4284799 | D10: LIBERADA | E10: 46315 | F10: 6 | G10: 3 | I10: 4284799 | J10: 10 | K10: POMAUT | L10: Troubleshooting nos paineis 87JX003 e 87 | M10: Troubleshooting nos paineis 87JX003 e 87 | N10: 1349-SYS87 | P10: 8 | Q10: VEND | R10: Z12 | S10: 46315
A11: MEC | B11: 419608810 | C11: 4196088 | D11: ABERTA | E11: 46315 | F11: 4 | G11: 2 | I11: 4196088 | J11: 10 | K11: POMMEC | L11: Parafuso do Redutor de giro quebrado | M11: Parafuso do Redutor de giro quebrado | N11: 1349-73MA002 | P11: 5 | Q11: VEND | R11: Z12 | S11: 46115
A12: MEC | B12: 436543710 | C12: 4365437 | D12: ENCERRADA | E12: 46313 | F12: 4 | G12: 2 | I12: 4365437 | J12: 10 | K12: MEC | L12: Realizar inspeção 71PI001A-D01 | M12: PRED_OLEO - 2600005802 - ANORMAL | N12: 1349-71PI001A-D01 | P12: 3 | Q12: DPRO | R12: Z10 | S12: 46298
A13: MEC | B13: 436543720 | C13: 4365437 | D13: ENCERRADA | E13: 46313 | F13: 4 | G13: 2 | I13: 4365437 | J13: 20 | K13: MEC | L13: Realizar coleta do óleo 71PI001A-D01 | M13: PRED_OLEO - 2600005802 - ANORMAL | N13: 1349-71PI001A-D01 | P13: 1 | Q13: DPRO | R13: Z10 | S13: 46298
A14: MEC | B14: 436543810 | C14: 4365438 | D14: ENCERRADA | E14: 46314 | F14: 4 | G14: 2 | I14: 4365438 | J14: 10 | K14: MEC | L14: Realizar inspeção 71PI001A-D01 | M14: PRED_OLEO - 2600030968 - ANORMAL | N14: 1349-71PI001A-D01 | P14: 3 | Q14: DPRO | R14: Z10 | S14: 46298
A15: MEC | B15: 436543820 | C15: 4365438 | D15: ENCERRADA | E15: 46314 | F15: 4 | G15: 2 | I15: 4365438 | J15: 20 | K15: MEC | L15: Realizar filtragem 71PI001A-D01 | M15: PRED_OLEO - 2600030968 - ANORMAL | N15: 1349-71PI001A-D01 | P15: 6 | Q15: DPRO | R15: Z10 | S15: 46298
A16: MEC | B16: 436544010 | C16: 4365440 | D16: ENCERRADA | E16: 46326 | F16: 4 | G16: 2 | I16: 4365440 | J16: 10 | K16: MEC | L16: Realizar filtragem 71P1001B-X01 | M16: PRED_OLEO - 2600005899 - ANORMAL | N16: 1349-71PI001B-X01 | P16: 6 | Q16: DPRO | R16: Z10 | S16: 46298
A17: MEC | B17: 436543910 | C17: 4365439 | D17: ENCERRADA | E17: 46326 | F17: 4 | G17: 2 | I17: 4365439 | J17: 10 | K17: MEC | L17: Realizar filtragem 84EG001-D01 | M17: PRED_OLEO - 2600030899 - ANORMAL | N17: 1349-84EG001-D01 | P17: 6 | Q17: DPRO | R17: Z10 | S17: 46298
A18: INS | B18: 436081110 | C18: 4360811 | D18: ENCERRADA | E18: 46318 | F18: 4 | G18: 1 | I18: 4360811 | J18: 10 | K18: INS | L18: Troubleshooting 85FSL0001 | M18: Troubleshooting 85FSL0001 | N18: 1349-85FSL0001 | P18: 6 | Q18: DPRO | R18: Z12 | S18: 46318
... A22: TER | B22: 434992330 | C22: 4349923 | D22: ABERTA | E22: 46326 | F22: 4 | G22: 2 | I22: 4349923 | J22: 30 | K22: TER | L22: VERIFICAÇÃO SISTEMA HIDRÁULICO GUINDASTE | M22: Checagem do sistema hidráulico K60E | N22: 1349-73MA002 | P22: 5 | Q22: VEND | R22: Z12 | S22: 46378
A23: ELE | B23: 438448810 | C23: 4384488 | D23: ENCERRADA | E23: 46316 | F23: 3 | G23: 2 | H23: 46316 | I23: 4384488 | J23: 10 | K23: POMELE | L23: 02W PREPARATION AND REPORT | M23: HIPOCHLORITE GENERATOR BIWEEKLY MAINT | N23: 1349-47XX001 | P23: 1 | Q23: PLANO | R23: Z12 | S23: 46316
A24: ELE | B24: 438448820 | C24: 4384488 | D24: ENCERRADA | E24: 46316 | F24: 3 | G24: 2 | H24: 46316 | I24: 4384488 | J24: 20 | K24: POMELE | L24: 02W ELECTROLYZER OPERATING PARAMETERS | M24: HIPOCHLORITE GENERATOR BIWEEKLY MAINT | N24: 1349-47XX001 | P24: 4 | Q24: PLANO | R24: Z12 | S24: 46316
A25: PRO | B25: 438448830 | C25: 4384488 | D25: LIBERADA | E25: 46316 | F25: 3 | G25: 2 | H25: 46316 | I25: 4384488 | J25: 30 | K25: POMPRO | L25: 02W ELECTROLYZER OPERATING PARAMETERS | M25: HIPOCHLORITE GENERATOR BIWEEKLY MAINT | N25: 1349-47XX001 | P25: 2 | Q25: PLANO | R25: Z12 | S25: 46316
A26: MEC | B26: 43844495 | C26: 4384449 | D26: LIBERADA | E26: 46320 | F26: 3 | G26: 2 | H26: 46320 | I26: 4384449 | J26: 5 | K26: POMMEC | L26: 02W PREPARATION AND REPORT | M26: STOP-U EAST CRANE DIESEL ENGINE | N26: 1349-73MA001 | P26: 1 | Q26: PLANO | R26: Z12 | S26: 46320
A27: MEC | B27: 438444920 | C27: 4384449 | D27: LIBERADA | E27: 46320 | F27: 3 | G27: 2 | H27: 46320 | I27: 4384449 | J27: 20 | K27: POMMEC | L27: 02W DIESEL ENGINE | M27: STOP-U EAST CRANE DIESEL ENGINE | N27: 1349-73MA001 | P27: 1 | Q27: PLANO | R27: Z12 | S27: 46320
A28: MEC | B28: 438444930 | C28: 4384449 | D28: LIBERADA | E28: 46320 | F28: 3 | G28: 2 | H28: 46320 | I28: 4384449 | J28: 30 | K28: POMMEC | L28: 02W DIESEL ENGINE OIL CHANGE | M28: STOP-U EAST CRANE DIESEL ENGINE | N28: 1349-73MA001 | P28: 2 | Q28: PLANO | R28: Z12 | S28: 46320
A29: ELE | B29: 438444940 | C29: 4384449 | D29: ENCERRADA | E29: 46320 | F29: 3 | G29: 2 | H29: 46320 | I29: 4384449 | J29: 40 | K29: POMELE | L29: 02W DIESEL ENGINE | M29: STOP-U EAST CRANE DIESEL ENGINE | N29: 1349-73MA001 | P29: 0.5 | Q29: PLANO | R29: Z12 | S29: 46320
A30: MEC | B30: 43845175 | C30: 4384517 | D30: ENCERRADA | E30: 46320 | F30: 3 | G30: 2 | H30: 46320 | I30: 4384517 | J30: 5 | K30: POMMEC | L30: 02W PREPARATION AND REPORT | M30: STOP-U EAST CRANE DIESEL ENGINE | N30: 1349-73MA001 | P30: 1 | Q30: PLANO | R30: Z12 | S30: 46320
A31: MEC | B31: 438451720 | C31: 4384517 | D31: ENCERRADA | E31: 46320 | F31: 3 | G31: 2 | H31: 46320 | I31: 4384517 | J31: 20 | K31: POMMEC | L31: 02W DIESEL ENGINE | M31: STOP-U EAST CRANE DIESEL ENGINE | N31: 1349-73MA001 | P31: 1 | Q31: PLANO | R31: Z12 | S31: 46320
A32: MEC | B32: 438451730 | C32: 4384517 | D32: ENCERRADA | E32: 46320 | F32: 3 | G32: 2 | H32: 46320 | I32: 4384517 | J32: 30 | K32: POMMEC | L32: 02W DIESEL ENGINE OIL CHANGE | M32: STOP-U EAST CRANE DIESEL ENGINE | N32: 1349-73MA001 | P32: 2 | Q32: PLANO | R32: Z12 | S32: 46320
A33: ELE | B33: 438451740 | C33: 4384517 | D33: ENCERRADA | E33: 46320 | F33: 3 | G33: 2 | H33: 46320 | I33: 4384517 | J33: 40 | K33: POMELE | L33: 02W DIESEL ENGINE | M33: STOP-U EAST CRANE DIESEL ENGINE | N33: 1349-73MA001 | P33: 0.5 | Q33: PLANO | R33: Z12 | S33: 46320
A34: MEC | B34: 43844535 | C34: 4384453 | D34: ENCERRADA | E34: 46320 | F34: 3 | G34: 2 | H34: 46320 | I34: 4384453 | J34: 5 | K34: POMMEC | L34: 02W PREPARATION AND REPORT | M34: STOP-U WEST CRANE DIESEL ENGINE | N34: 1349-73MA002 | P34: 1 | Q34: PLANO | R34: Z12 | S34: 46320
... A120: PRO | B120: 438651010 | C120: 4386510 | D120: ENCERRADA | E120: 46318 | F120: 5 | G120: 3 | H120: 46318 | I120: 4386510 | J120: 10 | K120: PRO | L120: INS-1813 INSP PRO FILTRO | M120: INSP FILTRO INS-1813 PRO 4M | N120: PERGC-PSIQ-UJQ-01-13 | P120: 3 | Q120: PLANO | R120: Z09 | S120: 46318
A121: ELE | B121: 439103210 | C121: 4391032 | D121: ABERTA | E121: 46326 | F121: 1 | G121: 1 | I121: 4391032 | J121: 10 | K121: ELE | L121: Manut corretiva UPS Iluminação B 85002B | M121: Manut corretiva UPS Iluminação B 85002B | N121: PERGC-FECC-UPS-01-10-01 | P121: 0 | Q121: AMAT | R121: Z12 | S121: 46310
A122: AUT | B122: 438946510 | C122: 4389465 | D122: LIBERADA | E122: 46326 | F122: 4 | G122: 2 | I122: 4389465 | J122: 10 | K122: AUT | L122: Troca dos componentes do radar sul | M122: Radar Sul com paradas intermitentes. | N122: PERGC-SDMT-PNN-04-10 | P122: 16 | Q122: VEND | R122: Z03 | S122: 46395
A123: CON | B123: 439189410 | C123: 4391894 | D123: ABERTA | E123: 46320 | F123: 6 | G123: 3 | I123: 4391894 | J123: 10 | K123: PIN | L123: TRAT. E PINT. TETO EXT. HV-LV | M123: TRAT. E PINT. TETO EXT. HV-LV | N123: PERGC | P123: 120 | Q123: PROG | R123: Z13 | S123: 46419
A124: CON | B124: 438954810 | C124: 4389548 | D124: ABERTA | E124: 46321 | F124: 4 | G124: 3 | I124: 4389548 | J124: 10 | K124: PIN | L124: PC RI:0001 REL:0837/24 24/06/2024 | M124: PC RI:0001 REL:0837/24 24/06/2024 | N124: PERGC-FSAC | P124: 68 | Q124: PROG | R124: Z01 | S124: 46562
A125: MEC | B125: 439338510 | C125: 4393385 | D125: ENCERRADA | E125: 46319 | F125: 6 | G125: 2 | I125: 4393385 | J125: 10 | K125: MEC | L125: Revisão do motor 50PS001B-M01 SWLP | M125: PRED_VIB - ROLAMENTO - SET26 SWIL | N125: PERGC-FSCA-MBB-10-04 | P125: 12 | Q125: DPRO | R125: Z12 | S125: 46319
A126: CON | B126: 438961210 | C126: 4389612 | D126: ABERTA | E126: 46321 | F126: 4 | G126: 3 | I126: 4389612 | J126: 10 | K126: PIN | L126: PC RI:0013 REL:0189/26 02/04/2026 | M126: PC RI:0013 REL:0189/26 02/04/2026 | N126: PERGC-FSRA | P126: 101 | Q126: PROG | R126: Z01 | S126: 47210
A127: CON | B127: 438959710 | C127: 4389597 | D127: ABERTA | E127: 46315 | F127: 4 | G127: 3 | I127: 4389597 | J127: 10 | K127: PIN | L127: PC RI:0023 REL:0187/26 31/03/2026 | M127: PC RI:0023 REL:0187/26 31/03/2026 | N127: PERGC-PSAI | P127: 35 | Q127: PROG | R127: Z01 | S127: 46843
A128: CON | B128: 438959810 | C128: 4389598 | D128: ABERTA | E128: 46315 | F128: 4 | G128: 3 | I128: 4389598 | J128: 10 | K128: PIN | L128: PC RI:0024 REL:0187/26 31/03/2026 | M128: PC RI:0024 REL:0187/26 31/03/2026 | N128: PERGC-PSAI | P128: 101 | Q128: PROG | R128: Z01 | S128: 46843
...

Sheet CALC
A1: é do dia? | B1: seq. | C1: total → | D1: =SUM(A2:A3001) | E1: col. Reprogramado → | F1: =IFERROR(MATCH("Reprogramado",BASELINE!$A$1:$ZZ$1,0),0)
A2: =IFERROR(IF(AND(BASELINE!I2<>"",INT(IF(CALC!$F$1>0,IF(N(INDEX(BASELINE!$A2:$ZZ2,CALC!$F$1))>0,N(INDEX(BASELINE!$A2:$ZZ2,CALC!$F$1)),N(BASELINE!E2)),N(BASELINE!E2)))=INT(SIMOPS!$D$3),IFERROR(UPPER(TRIM(BASELINE!D2&"")),"")<>"ENCERRADA"),1,0),0) | B2: =A2
A3: =IFERROR(IF(AND(BASELINE!I3<>"",INT(IF(CALC!$F$1>0,IF(N(INDEX(BASELINE!$A3:$ZZ3,CALC!$F$1))>0,N(INDEX(BASELINE!$A3:$ZZ3,CALC!$F$1)),N(BASELINE!E3)),N(BASELINE!E3)))=INT(SIMOPS!$D$3),IFERROR(UPPER(TRIM(BASELINE!D3&"")),"")<>"ENCERRADA"),1,0),0) | B3: =B2+A3
A4: =IFERROR(IF(AND(BASELINE!I4<>"",INT(IF(CALC!$F$1>0,IF(N(INDEX(BASELINE!$A4:$ZZ4,CALC!$F$1))>0,N(INDEX(BASELINE!$A4:$ZZ4,CALC!$F$1)),N(BASELINE!E4)),N(BASELINE!E4)))=INT(SIMOPS!$D$3),IFERROR(UPPER(TRIM(BASELINE!D4&"")),"")<>"ENCERRADA"),1,0),0) | B4: =B3+A4
A5: =IFERROR(IF(AND(BASELINE!I5<>"",INT(IF(CALC!$F$1>0,IF(N(INDEX(BASELINE!$A5:$ZZ5,CALC!$F$1))>0,N(INDEX(BASELINE!$A5:$ZZ5,CALC!$F$1)),N(BASELINE!E5)),N(BASELINE!E5)))=INT(SIMOPS!$D$3),IFERROR(UPPER(TRIM(BASELINE!D5&"")),"")<>"ENCERRADA"),1,0),0) | B5: =B4+A5
A6: =IFERROR(IF(AND(BASELINE!I6<>"",INT(IF(CALC!$F$1>0,IF(N(INDEX(BASELINE!$A6:$ZZ6,CALC!$F$1))>0,N(INDEX(BASELINE!$A6:$ZZ6,CALC!$F$1)),N(BASELINE!E6)),N(BASELINE!E6)))=INT(SIMOPS!$D$3),IFERROR(UPPER(TRIM(BASELINE!D6&"")),"")<>"ENCERRADA"),1,0),0) | B6: =B5+A6
A7: =IFERROR(IF(AND(BASELINE!I7<>"",INT(IF(CALC!$F$1>0,IF(N(INDEX(BASELINE!$A7:$ZZ7,CALC!$F$1))>0,N(INDEX(BASELINE!$A7:$ZZ7,CALC!$F$1)),N(BASELINE!E7)),N(BASELINE!E7)))=INT(SIMOPS!$D$3),IFERROR(UPPER(TRIM(BASELINE!D7&"")),"")<>"ENCERRADA"),1,0),0) | B7: =B6+A7
A8: =IFERROR(IF(AND(BASELINE!I8<>"",INT(IF(CALC!$F$1>0,IF(N(INDEX(BASELINE!$A8:$ZZ8,CALC!$F$1))>0,N(INDEX(BASELINE!$A8:$ZZ8,CALC!$F$1)),N(BASELINE!E8)),N(BASELINE!E8)))=INT(SIMOPS!$D$3),IFERROR(UPPER(TRIM(BASELINE!D8&"")),"")<>"ENCERRADA"),1,0),0) | B8: =B7+A8
A9: =IFERROR(IF(AND(BASELINE!I9<>"",INT(IF(CALC!$F$1>0,IF(N(INDEX(BASELINE!$A9:$ZZ9,CALC!$F$1))>0,N(INDEX(BASELINE!$A9:$ZZ9,CALC!$F$1)),N(BASELINE!E9)),N(BASELINE!E9)))=INT(SIMOPS!$D$3),IFERROR(UPPER(TRIM(BASELINE!D9&"")),"")<>"ENCERRADA"),1,0),0) | B9: =B8+A9
A10: =IFERROR(IF(AND(BASELINE!I10<>"",INT(IF(CALC!$F$1>0,IF(N(INDEX(BASELINE!$A10:$ZZ10,CALC!$F$1))>0,N(INDEX(BASELINE!$A10:$ZZ10,CALC!$F$1)),N(BASELINE!E10)),N(BASELINE!E10)))=INT(SIMOPS!$D$3),IFERROR(UPPER(TRIM(BASELINE!D10&"")),"")<>"ENCERRADA"),1,0),0) | B10: =B9+A10
A11: =IFERROR(IF(AND(BASELINE!I11<>"",INT(IF(CALC!$F$1>0,IF(N(INDEX(BASELINE!$A11:$ZZ11,CALC!$F$1))>0,N(INDEX(BASELINE!$A11:$ZZ11,CALC!$F$1)),N(BASELINE!E11)),N(BASELINE!E11)))=INT(SIMOPS!$D$3),IFERROR(UPPER(TRIM(BASELINE!D11&"")),"")<>"ENCERRADA"),1,0),0) | B11: =B10+A11
A12: =IFERROR(IF(AND(BASELINE!I12<>"",INT(IF(CALC!$F$1>0,IF(N(INDEX(BASELINE!$A12:$ZZ12,CALC!$F$1))>0,N(INDEX(BASELINE!$A12:$ZZ12,CALC!$F$1)),N(BASELINE!E12)),N(BASELINE!E12)))=INT(SIMOPS!$D$3),IFERROR(UPPER(TRIM(BASELINE!D12&"")),"")<>"ENCERRADA"),1,0),0) | B12: =B11+A12
A13: =IFERROR(IF(AND(BASELINE!I13<>"",INT(IF(CALC!$F$1>0,IF(N(INDEX(BASELINE!$A13:$ZZ13,CALC!$F$1))>0,N(INDEX(BASELINE!$A13:$ZZ13,CALC!$F$1)),N(BASELINE!E13)),N(BASELINE!E13)))=INT(SIMOPS!$D$3),IFERROR(UPPER(TRIM(BASELINE!D13&"")),"")<>"ENCERRADA"),1,0),0) | B13: =B12+A13
A14: =IFERROR(IF(AND(BASELINE!I14<>"",INT(IF(CALC!$F$1>0,IF(N(INDEX(BASELINE!$A14:$ZZ14,CALC!$F$1))>0,N(INDEX(BASELINE!$A14:$ZZ14,CALC!$F$1)),N(BASELINE!E14)),N(BASELINE!E14)))=INT(SIMOPS!$D$3),IFERROR(UPPER(TRIM(BASELINE!D14&"")),"")<>"ENCERRADA"),1,0),0) | B14: =B13+A14
... A3001: =IFERROR(IF(AND(BASELINE!I3001<>"",INT(IF(CALC!$F$1>0,IF(N(INDEX(BASELINE!$A3001:$ZZ3001,CALC!$F$1))>0,N(INDEX(BASELINE!$A3001:$ZZ3001,CALC!$F$1)),N(BASELINE!E3001)),N(BASELINE!E3001)))=INT(SIMOPS!$D$3),IFERROR(UPPER(TRIM(BASELINE!D3001&"")),"")<>"ENCERRADA"),1,0),0) | B3001: =B3000+A3001
